<?xml version="1.0" encoding="utf-8"?>
<!-- This URDF was automatically created by SolidWorks to URDF Exporter! Originally created by Stephen Brawner (brawner@gmail.com)
     Commit Version: 1.5.1-0-g916b5db  Build Version: 1.5.7152.31018
     For more information, please see http://wiki.ros.org/sw_urdf_exporter -->
<robot name="xiaotian">
    <link name="base_link">
        <inertial>
            <origin xyz="0.0001637 -0.00035131 0.00015086" rpy="0 0 0"/>
            <mass value="17.1764"/>
            <inertia ixx="0.027277" ixy="-3.356E-05" ixz="2.5047E-06" iyy="0.035385" iyz="-2.3484E-05" izz="0.050266"/>
        </inertial>
        <visual>
            <origin xyz="0 0 0" rpy="0 0 0"/>
            <geometry>
                <mesh filename="../meshes/base_link.STL"/>
            </geometry>
            <material name="">
                <color rgba="0.75294 0.75294 0.75294 1"/>
            </material>
        </visual>
        <collision>
            <origin xyz="0 0 0" rpy="0 0 0"/>
            <geometry>
                <mesh filename="../meshes/base_link.STL"/>
            </geometry>
        </collision>
    </link>
    <link name="fl_hip">
        <inertial>
            <origin xyz="0.068128 0.0022848 0.00038331" rpy="0 0 0"/>
            <mass value="0.44478"/>
            <inertia ixx="0.00044786" ixy="-5.5198E-06" ixz="-2.0327E-06" iyy="0.00058949" iyz="1.3226E-07" izz="0.00028792"/>
        </inertial>
        <visual>
            <origin xyz="0 0 0" rpy="0 0 0"/>
            <geometry>
                <mesh filename="../meshes/fl_hip.STL"/>
            </geometry>
            <material name="">
                <color rgba="0.75294 0.75294 0.75294 1"/>
            </material>
        </visual>
        <collision>
            <origin xyz="0 0 0" rpy="0 0 0"/>
            <geometry>
                <mesh filename="../meshes/fl_hip.STL"/>
            </geometry>
        </collision>
    </link>
    <joint name="fl_hip_roll" type="revolute">
        <origin xyz="0.2096 0.07 0" rpy="0 0 0"/>
        <parent link="base_link"/>
        <child link="fl_hip"/>
        <axis xyz="-1 0 0"/>
        <limit lower="-1.57" upper="1.57" effort="60" velocity="50"/>
    </joint>
    <link name="fl_thigh">
        <inertial>
            <origin xyz="-0.054147 0.071603 -0.00011951" rpy="0 0 0"/>
            <mass value="1.3429"/>
            <inertia ixx="0.00095898" ixy="1.1121E-05" ixz="-5.8753E-06" iyy="0.0028087" iyz="6.4767E-07" izz="0.0020781"/>
        </inertial>
        <visual>
            <origin xyz="0 0 0" rpy="0 0 0"/>
            <geometry>
                <mesh filename="../meshes/fl_thigh.STL"/>
            </geometry>
            <material name="">
                <color rgba="0.75294 0.75294 0.75294 1"/>
            </material>
        </visual>
        <collision>
            <origin xyz="0 0 0" rpy="0 0 0"/>
            <geometry>
                <mesh filename="../meshes/fl_thigh.STL"/>
            </geometry>
        </collision>
    </link>

    <joint name="fl_hip_pitch" type="revolute">
        <origin xyz="0.074 0.0189 0" rpy="0 0 0"/>
        <parent link="fl_hip"/>
        <child link="fl_thigh"/>
        <axis xyz="0 -1 0"/>
        <limit lower="-3.14" upper="0" effort="60" velocity="50"/>
    </joint>

    <link name="fl_calf">
        <inertial>
            <origin xyz="0.13129 -0.0071749 -0.056768" rpy="0 0 0"/>
            <mass value="0.39383"/>
            <inertia ixx="0.00012955" ixy="4.751E-06" ixz="0.00020885" iyy="0.0010985" iyz="-3.9901E-06" izz="0.0010198"/>
        </inertial>
        <visual>
            <origin xyz="0 0 0" rpy="0 0 0"/>
            <geometry>
                <mesh filename="../meshes/fl_calf.STL"/>
            </geometry>
            <material name="">
                <color rgba="0.75294 0.75294 0.75294 1"/>
            </material>
        </visual>
        <collision>
            <origin xyz="0 0 0" rpy="0 0 0"/>
            <geometry>
                <mesh filename="../meshes/fl_calf.STL"/>
            </geometry>
        </collision>
    </link>

    <joint name="fl_knee" type="revolute">
        <origin xyz="-0.26 0.0875 0" rpy="0 0 0"/>
        <parent link="fl_thigh"/>
        <child link="fl_calf"/>
        <axis xyz="0 -1 0"/>
        <limit lower="0" upper="3.14" effort="60" velocity="50"/>
    </joint>


    <link name="fl_wheel">
        <inertial>
            <origin xyz="1.54127264800907E-06 -0.000343350600955729 -4.72370035510539E-07" rpy="0 0 0"/>
            <mass value="0.0726229589307107"/>
            <inertia ixx="1.64185999936007E-05" ixy="1.76999732436665E-09" ixz="-7.77945641449359E-11" iyy="3.10088182474404E-05" iyz="-5.40019288163132E-10" izz="1.641835605391E-05"/>
        </inertial>
        <visual>
            <origin xyz="0 0 0" rpy="0 0 0"/>
            <geometry>
                <mesh filename="../meshes/fl_wheel.STL"/>
            </geometry>
            <material name="">
                <color rgba="0.898039215686275 0.917647058823529 0.929411764705882 1"/>
            </material>
        </visual>
        <collision>
            <origin xyz="0 0 0" rpy="0 0 0"/>
            <geometry>
                <mesh filename="../meshes/fl_wheel.STL"/>
            </geometry>
        </collision>
    </link>
    <joint name="fl_wheel" type="revolute">
        <origin xyz="0.24107 -0.0005 -0.1084" rpy="0 0 0"/>
        <parent link="fl_calf"/>
        <child link="fl_wheel"/>
        <axis xyz="0 -1 0"/>
        <limit lower="-1.57" upper="1.57" effort="60" velocity="50" />
    </joint>

    <link name="fr_hip">
        <inertial>
            <origin xyz="0.0686960645400227 -0.00217313177888925 0.000472810978072835" rpy="0 0 0"/>
            <mass value="0.448422171957628"/>
            <inertia ixx="0.000447895707537312" ixy="5.51582723792943E-06" ixz="2.16714411937878E-06" iyy="0.000589548151509867" iyz="1.83014483299849E-08" izz="0.000287954556145403"/>
        </inertial>
        <visual>
            <origin xyz="0 0 0" rpy="0 0 0"/>
            <geometry>
                <mesh filename="../meshes/fr_hip.STL"/>
            </geometry>
            <material name="">
                <color rgba="0.752941176470588 0.752941176470588 0.752941176470588 1"/>
            </material>
        </visual>
        <collision>
            <origin xyz="0 0 0" rpy="0 0 0"/>
            <geometry>
                <mesh filename="../meshes/fr_hip.STL"/>
            </geometry>
        </collision>
    </link>
    <joint name="fr_hip_roll" type="revolute">
        <origin xyz="0.2096 -0.07 0" rpy="0 0 0"/>
        <parent link="base_link"/>
        <child link="fr_hip"/>
        <axis xyz="-1 0 0"/>
        <limit lower="-1.57" upper="1.57" effort="60" velocity="50"/>
    </joint>
    <link name="fr_thigh">
        <inertial>
            <origin xyz="-0.0518054705425766 -0.071856343242158 -5.6776834512412E-05" rpy="0 0 0"/>
            <mass value="1.39795782352072"/>
            <inertia ixx="0.00109383163926102" ixy="-2.10857827131932E-05" ixz="6.34504438458413E-06" iyy="0.00300057191000295" iyz="6.20861828177988E-07" izz="0.00218329286999546"/>
        </inertial>
        <visual>
            <origin xyz="0 0 0" rpy="0 0 0"/>
            <geometry>
                <mesh filename="../meshes/fr_thigh.STL"/>
            </geometry>
            <material name="">
                <color rgba="0.752941176470588 0.752941176470588 0.752941176470588 1"/>
            </material>
        </visual>
        <collision>
            <origin xyz="0 0 0" rpy="0 0 0"/>
            <geometry>
                <mesh filename="../meshes/fr_thigh.STL"/>
            </geometry>
        </collision>
    </link>
    <joint name="fr_hip_pitch" type="revolute">
        <origin xyz="0.074 -0.0189 0" rpy="0 0 0"/>
        <parent link="fr_hip"/>
        <child link="fr_thigh"/>
        <axis xyz="0 1 0"/>
        <limit lower="-3.14" upper="0" effort="60" velocity="50"/>
    </joint>
    <link name="fr_calf">
        <inertial>
            <origin xyz="0.130801693969533 0.00714942801261559 -0.0568139509368908" rpy="0 0 0"/>
            <mass value="0.395347498939788"/>
            <inertia ixx="0.000129068476386095" ixy="-4.39089089966169E-06" ixz="0.000208721514997643" iyy="0.00109851935217986" iyz="4.45108024553873E-06" izz="0.00102034352196428"/>
        </inertial>
        <visual>
            <origin xyz="0 0 0" rpy="0 0 0"/>
            <geometry>
                <mesh filename="../meshes/fr_calf.STL"/>
            </geometry>
            <material name="">
                <color rgba="0.752941176470588 0.752941176470588 0.752941176470588 1"/>
            </material>
        </visual>
        <collision>
            <origin xyz="0 0 0" rpy="0 0 0"/>
            <geometry>
                <mesh filename="../meshes/fr_calf.STL"/>
            </geometry>
        </collision>
    </link>
    <joint name="fr_knee" type="revolute">
        <origin xyz="-0.26 -0.0875 0" rpy="0 0 0"/>
        <parent link="fr_thigh"/>
        <child link="fr_calf"/>
        <axis xyz="0 1 0"/>
        <limit lower="0" upper="3.14" effort="60" velocity="50"/>
    </joint>

    <link name="fr_wheel">
        <inertial>
            <origin xyz="8.29384199790839E-07 0.000343350477968796 -1.38092907737974E-06" rpy="0 0 0"/>
            <mass value="0.0726229800178101"/>
            <inertia ixx="1.64184158296075E-05" ixy="-9.52182185771799E-10" ixz="-1.30082969427632E-10" iyy="3.10088327954774E-05" iyz="1.58678494135709E-09" izz="1.64185548432923E-05"/>
        </inertial>
        <visual>
            <origin xyz="0 0 0" rpy="0 0 0"/>
            <geometry>
                <mesh filename="../meshes/fr_wheel.STL"/>
            </geometry>
            <material name="">
                <color rgba="0.752941176470588 0.752941176470588 0.752941176470588 1"/>
            </material>
        </visual>
        <collision>
            <origin xyz="0 0 0" rpy="0 0 0"/>
            <geometry>
                <mesh filename="../meshes/fr_wheel.STL"/>
            </geometry>
        </collision>
    </link>
    <joint name="fr_wheel" type="revolute">
        <origin xyz="0.24107 0.0005 -0.1084" rpy="0 0 0"/>
        <parent link="fr_calf"/>
        <child link="fr_wheel"/>
        <axis xyz="0 -1 0"/>
        <limit lower="-1.57" upper="1.57" effort="60" velocity="50" />
    </joint>

    <link name="rl_hip">
        <inertial>
            <origin xyz="-0.0686960722201718 0.0021731342230368 0.000472810288615511" rpy="0 0 0"/>
            <mass value="0.448422226100954"/>
            <inertia ixx="0.00044789571333425" ixy="5.5158349585492E-06" ixz="-2.16714612458135E-06" iyy="0.000589548154141695" iyz="-1.83092769084713E-08" izz="0.000287954566018092"/>
        </inertial>
        <visual>
            <origin xyz="0 0 0" rpy="0 0 0"/>
            <geometry>
                <mesh filename="../meshes/rl_hip.STL"/>
            </geometry>
            <material name="">
                <color rgba="0.752941176470588 0.752941176470588 0.752941176470588 1"/>
            </material>
        </visual>
        <collision>
            <origin xyz="0 0 0" rpy="0 0 0"/>
            <geometry>
                <mesh filename="../meshes/rl_hip.STL"/>
            </geometry>
        </collision>
    </link>
    <joint name="rl_hip_roll" type="revolute">
        <origin xyz="-0.2096 0.07 0" rpy="0 0 0"/>
        <parent link="base_link"/>
        <child link="rl_hip"/>
        <axis xyz="1 0 0"/>
        <limit lower="-1.57" upper="1.57" effort="60" velocity="50"/>
    </joint>
    <link name="rl_thigh">
        <inertial>
            <origin xyz="-0.0541473220841728 0.0716034495447507 -0.000119506269561503" rpy="0 0 0"/>
            <mass value="1.34293079219653"/>
            <inertia ixx="0.000958978080846605" ixy="1.11207391121183E-05" ixz="-5.87522840683726E-06" iyy="0.00280871646347873" iyz="6.47653609443264E-07" izz="0.00207811602618911"/>
        </inertial>
        <visual>
            <origin xyz="0 0 0" rpy="0 0 0"/>
            <geometry>
                <mesh filename="../meshes/rl_thigh.STL"/>
            </geometry>
            <material name="">
                <color rgba="0.752941176470588 0.752941176470588 0.752941176470588 1"/>
            </material>
        </visual>
        <collision>
            <origin xyz="0 0 0" rpy="0 0 0"/>
            <geometry>
                <mesh filename="../meshes/rl_thigh.STL"/>
            </geometry>
        </collision>
    </link>
    <joint name="rl_hip_pitch" type="revolute">
        <origin xyz="-0.074 0.0189 0" rpy="0 0 0"/>
        <parent link="rl_hip"/>
        <child link="rl_thigh"/>
        <axis xyz="0 -1 0"/>
        <limit lower="-3.14" upper="0" effort="60" velocity="50"/>
    </joint>
    <link name="rl_calf">
        <inertial>
            <origin xyz="0.13129 -0.0071749 -0.056768" rpy="0 0 0"/>
            <mass value="0.39383"/>
            <inertia ixx="0.00012955" ixy="4.751E-06" ixz="0.00020885" iyy="0.0010985" iyz="-3.9901E-06" izz="0.0010198"/>
        </inertial>
        <visual>
            <origin xyz="0 0 0" rpy="0 0 0"/>
            <geometry>
                <mesh filename="../meshes/rl_calf.STL"/>
            </geometry>
            <material name="">
                <color rgba="0.75294 0.75294 0.75294 1"/>
            </material>
        </visual>
        <collision>
            <origin xyz="0 0 0" rpy="0 0 0"/>
            <geometry>
                <mesh filename="../meshes/rl_calf.STL"/>
            </geometry>
        </collision>
    </link>
    <joint name="rl_knee" type="revolute">
        <origin xyz="-0.26 0.0875 0" rpy="0 0 0"/>
        <parent link="rl_thigh"/>
        <child link="rl_calf"/>
        <axis xyz="0 -1 0"/>
        <limit lower="0" upper="3.14" effort="60" velocity="50"/>
    </joint>

    <link name="rl_wheel">
        <inertial>
            <origin xyz="1.5379E-06 -0.00034335 -4.7251E-07" rpy="0 0 0"/>
            <mass value="0.072623"/>
            <inertia ixx="1.6419E-05" ixy="1.77E-09" ixz="-8.2332E-11" iyy="3.1009E-05" iyz="-5.4002E-10" izz="1.6418E-05"/>
        </inertial>
        <visual>
            <origin xyz="0 0 0" rpy="0 0 0"/>
            <geometry>
                <mesh filename="../meshes/rl_wheel.STL"/>
            </geometry>
            <material name="">
                <color rgba="0.75294 0.75294 0.75294 1"/>
            </material>
        </visual>
        <collision>
            <origin xyz="0 0 0" rpy="0 0 0"/>
            <geometry>
                <mesh filename="../meshes/rl_wheel.STL"/>
            </geometry>
        </collision>
    </link>
    <joint name="rl_wheel" type="revolute">
        <origin xyz="0.24107 -0.0005 -0.1084" rpy="0 0 0"/>
        <parent link="rl_calf"/>
        <child link="rl_wheel"/>
        <axis xyz="0 -1 0"/>
        <limit lower="-1.57" upper="1.57" effort="60" velocity="50"/>
    </joint>

    <link name="rr_hip">
        <inertial>
            <origin xyz="-0.0686960645400227 -0.00217313177888925 0.000472810978072835" rpy="0 0 0"/>
            <mass value="0.448422171957628"/>
            <inertia ixx="0.000447895707537312" ixy="-5.51582723792943E-06" ixz="2.16714411937878E-06" iyy="0.000589548151509867" iyz="-1.83014483299849E-08" izz="0.000287954556145403"/>
        </inertial>
        <visual>
            <origin xyz="0 0 0" rpy="0 0 0"/>
            <geometry>
                <mesh filename="../meshes/rr_hip.STL"/>
            </geometry>
            <material name="">
                <color rgba="0.752941176470588 0.752941176470588 0.752941176470588 1"/>
            </material>
        </visual>
        <collision>
            <origin xyz="0 0 0" rpy="0 0 0"/>
            <geometry>
                <mesh filename="../meshes/rr_hip.STL"/>
            </geometry>
        </collision>
    </link>
    <joint name="rr_hip_roll" type="revolute">
        <origin xyz="-0.2096 -0.07 0" rpy="0 0 0"/>
        <parent link="base_link"/>
        <child link="rr_hip"/>
        <axis xyz="1 0 0"/>
        <limit lower="-1.57" upper="1.57" effort="60" velocity="50"/>
    </joint>
    <link name="rr_thigh">
        <inertial>
            <origin xyz="-0.0518054705372448 -0.0718563432398833 -5.67768355083376E-05" rpy="0 0 0"/>
            <mass value="1.39795782336404"/>
            <inertia ixx="0.00109383163917954" ixy="-2.10857827223363E-05" ixz="6.34504447142691E-06" iyy="0.00300057190933612" iyz="6.20861820028977E-07" izz="0.00218329286940832"/>
        </inertial>
        <visual>
            <origin xyz="0 0 0" rpy="0 0 0"/>
            <geometry>
                <mesh filename="../meshes/rr_thigh.STL"/>
            </geometry>
            <material name="">
                <color rgba="0.752941176470588 0.752941176470588 0.752941176470588 1"/>
            </material>
        </visual>
        <collision>
            <origin xyz="0 0 0" rpy="0 0 0"/>
            <geometry>
                <mesh filename="../meshes/rr_thigh.STL"/>
            </geometry>
        </collision>
    </link>
    <joint name="rr_hip_pitch" type="revolute">
        <origin xyz="-0.074 -0.0189 0" rpy="0 0 0"/>
        <parent link="rr_hip"/>
        <child link="rr_thigh"/>
        <axis xyz="0 1 0"/>
        <limit lower="-3.14" upper="0" effort="60" velocity="50"/>
    </joint>
    <link name="rr_calf">
        <inertial>
            <origin xyz="0.130801693981397 0.00714942801534552 -0.0568139509419227" rpy="0 0 0"/>
            <mass value="0.395347498980154"/>
            <inertia ixx="0.000129068476385776" ixy="-4.39089090049954E-06" ixz="0.000208721514997669" iyy="0.00109851935218243" iyz="4.45108024519339E-06" izz="0.00102034352196753"/>
        </inertial>
        <visual>
            <origin xyz="0 0 0" rpy="0 0 0"/>
            <geometry>
                <mesh filename="../meshes/rr_calf.STL"/>
            </geometry>
            <material name="">
                <color rgba="0.752941176470588 0.752941176470588 0.752941176470588 1"/>
            </material>
        </visual>
        <collision>
            <origin xyz="0 0 0" rpy="0 0 0"/>
            <geometry>
                <mesh filename="../meshes/rr_calf.STL"/>
            </geometry>
        </collision>
    </link>
    <joint name="rr_knee" type="revolute">
        <origin xyz="-0.26 -0.0875 0" rpy="0 0 0"/>
        <parent link="rr_thigh"/>
        <child link="rr_calf"/>
        <axis xyz="0 1 0"/>
        <limit lower="0" upper="3.14" effort="60" velocity="50"/>
    </joint>


    <link name="rr_wheel">
        <inertial>
            <origin xyz="8.31527963374157E-07 0.000343350596184955 -1.3834866397569E-06" rpy="0 0 0"/>
            <mass value="0.0726229597928476"/>
            <inertia ixx="1.64184093260477E-05" ixy="-9.52168652716761E-10" ixz="-1.29761330494376E-10" iyy="3.10088188431438E-05" iyz="1.58676948720405E-09" izz="1.64185473202664E-05"/>
        </inertial>
        <visual>
            <origin xyz="0 0 0" rpy="0 0 0"/>
            <geometry>
                <mesh filename="../meshes/rr_wheel.STL"/>
            </geometry>
            <material name="">
                <color rgba="0.752941176470588 0.752941176470588 0.752941176470588 1"/>
            </material>
        </visual>
        <collision>
            <origin xyz="0 0 0" rpy="0 0 0"/>
            <geometry>
                <mesh filename="../meshes/rr_wheel.STL"/>
            </geometry>
        </collision>
    </link>
    <joint name="rr_wheel" type="revolute">
        <origin xyz="0.24107 0.0005 -0.1084" rpy="0 0 0"/>
        <parent link="rr_calf"/>
        <child link="rr_wheel"/>
        <axis xyz="0 -1 0"/>
        <limit lower="-1.57" upper="1.57" effort="60" velocity="50" />
    </joint>

</robot>