<?xml version="1.0" encoding="utf-8"?>
<!-- This URDF was automatically created by SolidWorks to URDF Exporter! Originally created by Stephen Brawner (brawner@gmail.com) 
     Commit Version: 1.6.0-1-g15f4949  Build Version: 1.6.7594.29634
     For more information, please see http://wiki.ros.org/sw_urdf_exporter -->
<robot
  name="assem_total">
  <link
    name="base_link">
    <inertial>
      <origin
        xyz="0.0019762 0.0028763 -0.00018184"
        rpy="0 0 0" />
      <mass
        value="8.117" />
      <inertia
        ixx="0.028464"
        ixy="-4.1944E-05"
        ixz="5.6278E-06"
        iyy="0.036161"
        iyz="-2.6291E-05"
        izz="0.051159" />
    </inertial>
    <visual>
      <origin
        xyz="0 0 0"
        rpy="0 0 0" />
      <geometry>
        <mesh
          filename="package://assem_total/meshes/base_link.STL" />
      </geometry>
      <material
        name="">
        <color
          rgba="0.75294 0.75294 0.75294 1" />
      </material>
    </visual>
    <collision>
      <origin
        xyz="0 0 0"
        rpy="0 0 0" />
      <geometry>
        <mesh
          filename="package://assem_total/meshes/base_link.STL" />
      </geometry>
    </collision>
  </link>
  <link
    name="fr_hip_roll">
    <inertial>
    <origin
        xyz="-0.0038954 -0.042925 0.00044671"
        rpy="0 0 0" />
      <mass
        value="0.79523" />
      <inertia
        ixx="0.00075367"
        ixy="8.7084E-06"
        ixz="5.3738E-06"
        iyy="0.0011365"
        iyz="8.5453E-07"
        izz="0.00057451" />
    </inertial>
    <visual>
      <origin
        xyz="0 0 0"
        rpy="0 0 0" />
      <geometry>
        <mesh
          filename="package://assem_total/meshes/fr_hip_roll.STL" />
      </geometry>
      <material
        name="">
        <color
          rgba="0.75294 0.75294 0.75294 1" />
      </material>
    </visual>
    <collision>
      <origin
        xyz="0 0 0"
        rpy="0 0 0" />
      <geometry>
        <mesh
          filename="package://assem_total/meshes/fr_hip_roll.STL" />
      </geometry>
    </collision>
  </link>
  <joint
    name="fr_hip_roll"
    type="revolute">
    <origin
      xyz="0.2836 -0.07 0"
      rpy="0 0 0" />
    <parent
      link="base_link" />
    <child
      link="fr_hip_roll" />
    <axis
      xyz="-1 0 0" />
    <limit
      lower="-3.14"
      upper="3.14"
      effort="100"
      velocity="1" />
  </joint>
  <link
    name="fr_hip_pitch">
    <inertial>
      <origin
        xyz="-0.088696 -0.10454 -0.029907"
        rpy="0 0 0" />
      <mass
        value="0.60323" />
      <inertia
        ixx="0.00042921"
        ixy="-1.1921E-05"
        ixz="-0.00027681"
        iyy="0.001464"
        iyz="-1.1082E-05"
        izz="0.0011563" />
    </inertial>
    <visual>
      <origin
        xyz="0 0 0"
        rpy="0 0 0" />
      <geometry>
        <mesh
          filename="package://assem_total/meshes/fr_hip_pitch.STL" />
      </geometry>
      <material
        name="">
        <color
          rgba="0.75294 0.75294 0.75294 1" />
      </material>
    </visual>
    <collision>
      <origin
        xyz="0 0 0"
        rpy="0 0 0" />
      <geometry>
        <mesh
          filename="package://assem_total/meshes/fr_hip_pitch.STL" />
      </geometry>
    </collision>
  </link>
  <joint
    name="fr_hip_pitch"
    type="revolute">
    <origin
      xyz="0 0 0"
      rpy="0 0 0" />
    <parent
      link="fr_hip_roll" />
    <child
      link="fr_hip_pitch" />
    <axis
      xyz="0 1 0" />
    <limit
      lower="-3.14"
      upper="3.14"
      effort="100"
      velocity="1" />
  </joint>
  <link
    name="fr_knee">
    <inertial>
      <origin
        xyz="0.11645 0.0029035 -0.0081089"
        rpy="0 0 0" />
      <mass
        value="0.4765" />
      <inertia
        ixx="0.00012829"
        ixy="9.2786E-06"
        ixz="-0.00011867"
        iyy="0.0012471"
        iyz="4.4011E-06"
        izz="0.0011655" />
    </inertial>
    <visual>
      <origin
        xyz="0 0 0"
        rpy="0 0 0" />
      <geometry>
        <mesh
          filename="package://assem_total/meshes/fr_knee.STL" />
      </geometry>
      <material
        name="">
        <color
          rgba="0.75294 0.75294 0.75294 1" />
      </material>
    </visual>
    <collision>
      <origin
        xyz="0 0 0"
        rpy="0 0 0" />
      <geometry>
        <mesh
          filename="package://assem_total/meshes/fr_knee.STL" />
      </geometry>
    </collision>
  </link>
  <joint
    name="fr_knee"
    type="revolute">
    <origin
      xyz="-0.24369 -0.1033 -0.082796"
      rpy="0 0 0" />
    <parent
      link="fr_hip_pitch" />
    <child
      link="fr_knee" />
    <axis
      xyz="0 1 0" />
    <limit
      lower="-3.14"
      upper="3.14"
      effort="100"
      velocity="1" />
  </joint>
  <link
    name="fr_wheel">
    <inertial>
      <origin
        xyz="1.3878E-17 0.0004807 1.3878E-17"
        rpy="0 0 0" />
      <mass
        value="0.050733" />
      <inertia
        ixx="1.4301E-05"
        ixy="-7.6347E-21"
        ixz="-4.8546E-15"
        iyy="2.7852E-05"
        iyz="-2.0362E-20"
        izz="1.4301E-05" />
    </inertial>
    <visual>
      <origin
        xyz="0 0 0"
        rpy="0 0 0" />
      <geometry>
        <mesh
          filename="package://assem_total/meshes/fr_wheel.STL" />
      </geometry>
      <material
        name="">
        <color
          rgba="0.89804 0.91765 0.92941 1" />
      </material>
    </visual>
    <collision>
      <origin
        xyz="0 0 0"
        rpy="0 0 0" />
      <geometry>
        <mesh
          filename="package://assem_total/meshes/fr_wheel.STL" />
      </geometry>
    </collision>
  </link>
  <joint
    name="fr_wheel"
    type="revolute">
    <origin
      xyz="0.26353 0.0005 -0.021593"
      rpy="0 0 0" />
    <parent
      link="fr_knee" />
    <child
      link="fr_wheel" />
    <axis
      xyz="0 1 0" />
    <limit
      lower="-3.14"
      upper="3.14"
      effort="100"
      velocity="1" />
  </joint>
  <link
    name="fl_hip_roll">
    <inertial>
      <origin
        xyz="-0.0039022 0.042911 0.00046681"
        rpy="0 0 0" />
      <mass
        value="0.79523" />
      <inertia
        ixx="0.00075378"
        ixy="-8.6673E-06"
        ixz="5.2319E-06"
        iyy="0.0011365"
        iyz="-9.7257E-07"
        izz="0.0005744" />
    </inertial>
    <visual>
      <origin
        xyz="0 0 0"
        rpy="0 0 0" />
      <geometry>
        <mesh
          filename="package://assem_total/meshes/fl_hip_roll.STL" />
      </geometry>
      <material
        name="">
        <color
          rgba="0.75294 0.75294 0.75294 1" />
      </material>
    </visual>
    <collision>
      <origin
        xyz="0 0 0"
        rpy="0 0 0" />
      <geometry>
        <mesh
          filename="package://assem_total/meshes/fl_hip_roll.STL" />
      </geometry>
    </collision>
  </link>
  <joint
    name="fl_hip_roll"
    type="revolute">
    <origin
      xyz="0.2836 0.07 0"
      rpy="0 0 0" />
    <parent
      link="base_link" />
    <child
      link="fl_hip_roll" />
    <axis
      xyz="-1 0 0" />
    <limit
      lower="-3.14"
      upper="3.14"
      effort="100"
      velocity="1" />
  </joint>
  <link
    name="fl_hip_pitch">
    <inertial>
      <origin
        xyz="-0.088742 0.10453 -0.029914"
        rpy="0 0 0" />
      <mass
        value="0.60372" />
      <inertia
        ixx="0.00042927"
        ixy="1.192E-05"
        ixz="-0.00027679"
        iyy="0.001464"
        iyz="1.1087E-05"
        izz="0.0011563" />
    </inertial>
    <visual>
      <origin
        xyz="0 0 0"
        rpy="0 0 0" />
      <geometry>
        <mesh
          filename="package://assem_total/meshes/fl_hip_pitch.STL" />
      </geometry>
      <material
        name="">
        <color
          rgba="0.75294 0.75294 0.75294 1" />
      </material>
    </visual>
    <collision>
      <origin
        xyz="0 0 0"
        rpy="0 0 0" />
      <geometry>
        <mesh
          filename="package://assem_total/meshes/fl_hip_pitch.STL" />
      </geometry>
    </collision>
  </link>
  <joint
    name="fl_hip_pitch"
    type="revolute">
    <origin
      xyz="0 0 0"
      rpy="0 0 0" />
    <parent
      link="fl_hip_roll" />
    <child
      link="fl_hip_pitch" />
    <axis
      xyz="0 -1 0" />
    <limit
      lower="-3.14"
      upper="3.14"
      effort="100"
      velocity="1" />
  </joint>
  <link
    name="fl_knee_joint">
    <inertial>
      <origin
        xyz="0.11733 -0.0030152 -0.0079987"
        rpy="0 0 0" />
      <mass
        value="0.47753" />
      <inertia
        ixx="0.00012832"
        ixy="-9.279E-06"
        ixz="-0.00011867"
        iyy="0.001247"
        iyz="-4.4072E-06"
        izz="0.0011655" />
    </inertial>
    <visual>
      <origin
        xyz="0 0 0"
        rpy="0 0 0" />
      <geometry>
        <mesh
          filename="package://assem_total/meshes/fl_knee_joint.STL" />
      </geometry>
      <material
        name="">
        <color
          rgba="0.75294 0.75294 0.75294 1" />
      </material>
    </visual>
    <collision>
      <origin
        xyz="0 0 0"
        rpy="0 0 0" />
      <geometry>
        <mesh
          filename="package://assem_total/meshes/fl_knee_joint.STL" />
      </geometry>
    </collision>
  </link>
  <joint
    name="fl_knee_joint"
    type="revolute">
    <origin
      xyz="-0.24369 0.1033 -0.082796"
      rpy="0 0 0" />
    <parent
      link="fl_hip_pitch" />
    <child
      link="fl_knee_joint" />
    <axis
      xyz="0 -1 0" />
    <limit
      lower="-3.14"
      upper="3.14"
      effort="100"
      velocity="1" />
  </joint>
  <link
    name="fl_wheel">
    <inertial>
      <origin
        xyz="-1.3878E-17 -0.0004807 6.9389E-18"
        rpy="0 0 0" />
      <mass
        value="0.050733" />
      <inertia
        ixx="1.4301E-05"
        ixy="1.8368E-19"
        ixz="-3.166E-15"
        iyy="2.7852E-05"
        iyz="-2.0495E-20"
        izz="1.4301E-05" />
    </inertial>
    <visual>
      <origin
        xyz="0 0 0"
        rpy="0 0 0" />
      <geometry>
        <mesh
          filename="package://assem_total/meshes/fl_wheel.STL" />
      </geometry>
      <material
        name="">
        <color
          rgba="0.89804 0.91765 0.92941 1" />
      </material>
    </visual>
    <collision>
      <origin
        xyz="0 0 0"
        rpy="0 0 0" />
      <geometry>
        <mesh
          filename="package://assem_total/meshes/fl_wheel.STL" />
      </geometry>
    </collision>
  </link>
  <joint
    name="fl_wheel"
    type="revolute">
    <origin
      xyz="0.26353 -0.0005 -0.021593"
      rpy="0 0 0" />
    <parent
      link="fl_knee_joint" />
    <child
      link="fl_wheel" />
    <axis
      xyz="0 -1 0" />
    <limit
      lower="-3.14"
      upper="3.14"
      effort="100"
      velocity="1" />
  </joint>
  <link
    name="hl_hip_roll">
    <inertial>
      <origin
        xyz="0.0054099 0.043026 0.00046416"
        rpy="0 0 0" />
      <mass
        value="0.79324" />
      <inertia
        ixx="0.00075357"
        ixy="2.878E-06"
        ixz="5.087E-06"
        iyy="0.0011364"
        iyz="-9.4715E-07"
        izz="0.0005743" />
    </inertial>
    <visual>
      <origin
        xyz="0 0 0"
        rpy="0 0 0" />
      <geometry>
        <mesh
          filename="package://assem_total/meshes/hl_hip_roll.STL" />
      </geometry>
      <material
        name="">
        <color
          rgba="0.75294 0.75294 0.75294 1" />
      </material>
    </visual>
    <collision>
      <origin
        xyz="0 0 0"
        rpy="0 0 0" />
      <geometry>
        <mesh
          filename="package://assem_total/meshes/hl_hip_roll.STL" />
      </geometry>
    </collision>
  </link>
  <joint
    name="hl_hip_roll"
    type="revolute">
    <origin
      xyz="-0.2836 0.07 0"
      rpy="0 0 0" />
    <parent
      link="base_link" />
    <child
      link="hl_hip_roll" />
    <axis
      xyz="1 0 0" />
    <limit
      lower="-3.14"
      upper="3.14"
      effort="100"
      velocity="1" />
  </joint>
  <link
    name="hl_hip_pitch">
    <inertial>
      <origin
        xyz="-0.088742 0.10453 -0.029914"
        rpy="0 0 0" />
      <mass
        value="0.60372" />
      <inertia
        ixx="0.00042927"
        ixy="1.192E-05"
        ixz="-0.00027679"
        iyy="0.001464"
        iyz="1.1087E-05"
        izz="0.0011563" />
    </inertial>
    <visual>
      <origin
        xyz="0 0 0"
        rpy="0 0 0" />
      <geometry>
        <mesh
          filename="package://assem_total/meshes/hl_hip_pitch.STL" />
      </geometry>
      <material
        name="">
        <color
          rgba="0.75294 0.75294 0.75294 1" />
      </material>
    </visual>
    <collision>
      <origin
        xyz="0 0 0"
        rpy="0 0 0" />
      <geometry>
        <mesh
          filename="package://assem_total/meshes/hl_hip_pitch.STL" />
      </geometry>
    </collision>
  </link>
  <joint
    name="hl_hip_pitch"
    type="revolute">
    <origin
      xyz="0 0 0"
      rpy="0 0 0" />
    <parent
      link="hl_hip_roll" />
    <child
      link="hl_hip_pitch" />
    <axis
      xyz="0 -1 0" />
    <limit
      lower="-3.14"
      upper="3.14"
      effort="100"
      velocity="1" />
  </joint>
  <link
    name="hl_knee">
    <inertial>
      <origin
        xyz="0.11761 -0.0029805 -0.0080407"
        rpy="0 0 0" />
      <mass
        value="0.4784" />
      <inertia
        ixx="0.00012837"
        ixy="-9.279E-06"
        ixz="-0.00011868"
        iyy="0.0012471"
        iyz="-4.407E-06"
        izz="0.0011655" />
    </inertial>
    <visual>
      <origin
        xyz="0 0 0"
        rpy="0 0 0" />
      <geometry>
        <mesh
          filename="package://assem_total/meshes/hl_knee.STL" />
      </geometry>
      <material
        name="">
        <color
          rgba="0.75294 0.75294 0.75294 1" />
      </material>
    </visual>
    <collision>
      <origin
        xyz="0 0 0"
        rpy="0 0 0" />
      <geometry>
        <mesh
          filename="package://assem_total/meshes/hl_knee.STL" />
      </geometry>
    </collision>
  </link>
  <joint
    name="hl_knee"
    type="revolute">
    <origin
      xyz="-0.24369 0.1033 -0.082796"
      rpy="0 0 0" />
    <parent
      link="hl_hip_pitch" />
    <child
      link="hl_knee" />
    <axis
      xyz="0 -1 0" />
    <limit
      lower="-3.14"
      upper="3.14"
      effort="100"
      velocity="1" />
  </joint>
  <link
    name="hl_wheel">
    <inertial>
      <origin
        xyz="1.1102E-16 -0.0004807 0"
        rpy="0 0 0" />
      <mass
        value="0.050733" />
      <inertia
        ixx="1.4301E-05"
        ixy="3.303E-20"
        ixz="-3.166E-15"
        iyy="2.7852E-05"
        iyz="-9.6306E-21"
        izz="1.4301E-05" />
    </inertial>
    <visual>
      <origin
        xyz="0 0 0"
        rpy="0 0 0" />
      <geometry>
        <mesh
          filename="package://assem_total/meshes/hl_wheel.STL" />
      </geometry>
      <material
        name="">
        <color
          rgba="0.89804 0.91765 0.92941 1" />
      </material>
    </visual>
    <collision>
      <origin
        xyz="0 0 0"
        rpy="0 0 0" />
      <geometry>
        <mesh
          filename="package://assem_total/meshes/hl_wheel.STL" />
      </geometry>
    </collision>
  </link>
  <joint
    name="hl_wheel"
    type="revolute">
    <origin
      xyz="0.26353 -0.0005 -0.021593"
      rpy="0 0 0" />
    <parent
      link="hl_knee" />
    <child
      link="hl_wheel" />
    <axis
      xyz="0 -1 0" />
    <limit
      lower="-3.14"
      upper="3.14"
      effort="100"
      velocity="1" />
  </joint>
  <link
    name="hr_hip_roll">
    <inertial>
      <origin
        xyz="0.0054167 -0.043026 0.00044414"
        rpy="0 0 0" />
      <mass
        value="0.79324" />
      <inertia
        ixx="0.00075346"
        ixy="-2.8548E-06"
        ixz="5.229E-06"
        iyy="0.0011364"
        iyz="8.7994E-07"
        izz="0.00057441" />
    </inertial>
    <visual>
      <origin
        xyz="0 0 0"
        rpy="0 0 0" />
      <geometry>
        <mesh
          filename="package://assem_total/meshes/hr_hip_roll.STL" />
      </geometry>
      <material
        name="">
        <color
          rgba="0.75294 0.75294 0.75294 1" />
      </material>
    </visual>
    <collision>
      <origin
        xyz="0 0 0"
        rpy="0 0 0" />
      <geometry>
        <mesh
          filename="package://assem_total/meshes/hr_hip_roll.STL" />
      </geometry>
    </collision>
  </link>
  <joint
    name="hr_hip_roll"
    type="revolute">
    <origin
      xyz="-0.2836 -0.07 0"
      rpy="0 0 0" />
    <parent
      link="base_link" />
    <child
      link="hr_hip_roll" />
    <axis
      xyz="1 0 0" />
    <limit
      lower="-3.14"
      upper="3.14"
      effort="100"
      velocity="1" />
  </joint>
  <link
    name="hr_hip_pitch">
    <inertial>
      <origin
        xyz="-0.088696 -0.10454 -0.029907"
        rpy="0 0 0" />
      <mass
        value="0.60323" />
      <inertia
        ixx="0.00042921"
        ixy="-1.1921E-05"
        ixz="-0.00027681"
        iyy="0.001464"
        iyz="-1.1082E-05"
        izz="0.0011563" />
    </inertial>
    <visual>
      <origin
        xyz="0 0 0"
        rpy="0 0 0" />
      <geometry>
        <mesh
          filename="package://assem_total/meshes/hr_hip_pitch.STL" />
      </geometry>
      <material
        name="">
        <color
          rgba="0.75294 0.75294 0.75294 1" />
      </material>
    </visual>
    <collision>
      <origin
        xyz="0 0 0"
        rpy="0 0 0" />
      <geometry>
        <mesh
          filename="package://assem_total/meshes/hr_hip_pitch.STL" />
      </geometry>
    </collision>
  </link>
  <joint
    name="hr_hip_pitch"
    type="revolute">
    <origin
      xyz="0 0 0"
      rpy="0 0 0" />
    <parent
      link="hr_hip_roll" />
    <child
      link="hr_hip_pitch" />
    <axis
      xyz="0 1 0" />
    <limit
      lower="-3.14"
      upper="3.14"
      effort="100"
      velocity="1" />
  </joint>
  <link
    name="hr_knee">
    <inertial>
      <origin
        xyz="0.11648 0.0029054 -0.0081109"
        rpy="0 0 0" />
      <mass
        value="0.47658" />
      <inertia
        ixx="0.0001283"
        ixy="9.2786E-06"
        ixz="-0.00011867"
        iyy="0.0012471"
        iyz="4.4011E-06"
        izz="0.0011655" />
    </inertial>
    <visual>
      <origin
        xyz="0 0 0"
        rpy="0 0 0" />
      <geometry>
        <mesh
          filename="package://assem_total/meshes/hr_knee.STL" />
      </geometry>
      <material
        name="">
        <color
          rgba="0.75294 0.75294 0.75294 1" />
      </material>
    </visual>
    <collision>
      <origin
        xyz="0 0 0"
        rpy="0 0 0" />
      <geometry>
        <mesh
          filename="package://assem_total/meshes/hr_knee.STL" />
      </geometry>
    </collision>
  </link>
  <joint
    name="hr_knee"
    type="revolute">
    <origin
      xyz="-0.24369 -0.1033 -0.082796"
      rpy="0 0 0" />
    <parent
      link="hr_hip_pitch" />
    <child
      link="hr_knee" />
    <axis
      xyz="0 1 0" />
    <limit
      lower="-3.14"
      upper="3.14"
      effort="100"
      velocity="1" />
  </joint>
  <link
    name="hr_wheel">
    <inertial>
      <origin
        xyz="1.1102E-16 0.0004807 -1.3878E-17"
        rpy="0 0 0" />
      <mass
        value="0.050733" />
      <inertia
        ixx="1.4301E-05"
        ixy="2.8774E-21"
        ixz="-4.8546E-15"
        iyy="2.7852E-05"
        iyz="-8.0971E-21"
        izz="1.4301E-05" />
    </inertial>
    <visual>
      <origin
        xyz="0 0 0"
        rpy="0 0 0" />
      <geometry>
        <mesh
          filename="package://assem_total/meshes/hr_wheel.STL" />
      </geometry>
      <material
        name="">
        <color
          rgba="0.75294 0.75294 0.75294 1" />
      </material>
    </visual>
    <collision>
      <origin
        xyz="0 0 0"
        rpy="0 0 0" />
      <geometry>
        <mesh
          filename="package://assem_total/meshes/hr_wheel.STL" />
      </geometry>
    </collision>
  </link>
  <joint
    name="hr_wheel"
    type="revolute">
    <origin
      xyz="0.26353 0.0005 -0.021593"
      rpy="0 0 0" />
    <parent
      link="hr_knee" />
    <child
      link="hr_wheel" />
    <axis
      xyz="0 1 0" />
    <limit
      lower="-3.14"
      upper="3.14"
      effort="100"
      velocity="1" />
  </joint>
</robot>