<?xml version="1.0" encoding="utf-8"?>
<!-- This URDF was automatically created by SolidWorks to URDF Exporter! Originally created by Stephen Brawner (brawner@gmail.com)
     Commit Version: 1.5.1-0-g916b5db  Build Version: 1.5.7152.31018
     For more information, please see http://wiki.ros.org/sw_urdf_exporter -->
<robot name="xiaotian">
    <mujoco>
        <compiler meshdir="./meshes_nw/" balanceinertia="false"/>
    </mujoco>
    <!-- <link name="root" />
    <joint name="root_joint" type="revolute">
        <origin xyz="0.2096 0.07 0" rpy="0 0 0"/>
        <parent link="root"/>
        <child link="base_link"/>
        <axis xyz="-1 0 0"/>
        <limit lower="-1.57" upper="1.57" effort="60" velocity="50"/>
    </joint> -->
    <link name="base_link">
        <!-- <inertial>
            <origin xyz="0.04E-03 -0.39E-03 0.01E-03" rpy="0 0 0"/>
            <mass value="7779.84E-03"/>
            <inertia ixx="54257208.06E-09" ixy="-166305.23E-09" ixz="11534.26E-09" iyy="301277442.68E-09" iyz="-136908.76E-09" izz="335864319.39E-09"/>
        </inertial> -->
        <inertial>
            <origin xyz="0.22E-03 -0.44E-03 -0.03E-03" rpy="0 0 0"/>
            <mass value="11978.84E-03"/>
            <inertia ixx="74441377.08E-09" ixy="-124704.84E-09" ixz="-25701.76E-09" iyy="312967306.09E-09" iyz="-134276.32E-09" izz="362528466.40E-09"/>
        </inertial>
        <visual>
            <origin xyz="0 0 0" rpy="0 0 0"/>
            <geometry>
                <mesh filename="meshes_nw/base_link.STL"/>
            </geometry>
            <material name="">
                <color rgba="0.75294 0.75294 0.75294 1"/>
            </material>
        </visual>
        <collision>
            <origin xyz="0 0 0" rpy="0 0 0"/>
            <geometry>
                <mesh filename="meshes_nw/base_link.STL"/>
            </geometry>
        </collision>
    </link>
    <link name="fl_hip">
        <inertial>
            <origin xyz="72.35E-03 0.30E-03 0.000" rpy="0 0 0"/>
            <mass value="1519.39E-03"/>
            <inertia ixx="1694040.51E-09" ixy="-771.73E-09" ixz="13604.23E-09" iyy="3302452.37E-09" iyz="4147.49E-09" izz="2258493.73E-09"/>
        </inertial>
        <visual>
            <origin xyz="0 0 0" rpy="0 0 0"/>
            <geometry>
                <mesh filename="meshes_nw/fl_hip.STL"/>
            </geometry>
            <material name="">
                <color rgba="0.75294 0.75294 0.75294 1"/>
            </material>
        </visual>
        <collision>
            <origin xyz="0 0 0" rpy="0 0 0"/>
            <geometry>
                <mesh filename="meshes_nw/fl_hip.STL"/>
            </geometry>
        </collision>
    </link>
    <joint name="fl_hip_roll" type="revolute">
        <origin xyz="0.2096 0.07 0" rpy="0 0 0"/>
        <parent link="base_link"/>
        <child link="fl_hip"/>
        <axis xyz="-1 0 0"/>
        <limit lower="-1.57" upper="1.57" effort="60" velocity="50"/>
    </joint>
    <link name="fl_thigh">
        <inertial>
            <origin xyz="-31.16E-03 60.66E-03 0.02E-03" rpy="0 0 0"/>
            <mass value="2324.70E-03"/>
            <inertia ixx="3245856.06E-09" ixy="-1927888.88E-09" ixz="16621.48E-09" iyy="14234186.83E-09" iyz="3681.40E-09" izz="13967700.29E-09"/>
        </inertial>
        <visual>
            <origin xyz="0 0 0" rpy="0 0 0"/>
            <geometry>
                <mesh filename="meshes_nw/fl_thigh.STL"/>
            </geometry>
            <material name="">
                <color rgba="0.75294 0.75294 0.75294 1"/>
            </material>
        </visual>
        <collision>
            <origin xyz="0 0 0" rpy="0 0 0"/>
            <geometry>
                <mesh filename="meshes_nw/fl_thigh.STL"/>
            </geometry>
        </collision>
    </link>

    <joint name="fl_hip_pitch" type="revolute">
        <origin xyz="0.074 0.0189 0" rpy="0 0 0"/>
        <parent link="fl_hip"/>
        <child link="fl_thigh"/>
        <axis xyz="0 -1 0"/>
        <limit lower="-3.14" upper="0" effort="60" velocity="50"/>
    </joint>

    <link name="fl_calf">
        <inertial>
            <origin xyz="0.13129 -0.0071749 -0.056768" rpy="0 0 0"/>
            <mass value="0.39383"/>
            <inertia ixx="0.00012955" ixy="4.751E-06" ixz="0.00020885" iyy="0.0010985" iyz="-3.9901E-06" izz="0.0010198"/>
        </inertial>
        <visual>
            <origin xyz="0 0 0" rpy="0 0 0"/>
            <geometry>
                <mesh filename="meshes_nw/fl_calf.STL"/>
            </geometry>
            <material name="">
                <color rgba="0.75294 0.75294 0.75294 1"/>
            </material>
        </visual>
        <collision>
            <origin xyz="0 0 0" rpy="0 0 0"/>
            <geometry>
                <mesh filename="meshes_nw/fl_calf.STL"/>
            </geometry>
        </collision>
    </link>

    <joint name="fl_knee" type="revolute">
        <origin xyz="-0.26 0.0875 0" rpy="0 0 0"/>
        <parent link="fl_thigh"/>
        <child link="fl_calf"/>
        <axis xyz="0 -1 0"/>
        <limit lower="0" upper="3.14" effort="60" velocity="50"/>
    </joint>


    <link name="fl_wheel">
        <inertial>
            <origin xyz="-6.4629E-05 5.464E-05 0.0011936" rpy="0 0 0" />
            <mass value="0.023963" />
            <inertia ixx="2.4232E-06" ixy="1.7509E-08" ixz="3.4689E-07" iyy="3.7765E-06" iyz="-1.0175E-08" izz="4.0982E-06" />
        </inertial>
        <visual>
            <origin xyz="0 0 0" rpy="0 0 0" />
            <geometry>
                <mesh filename="meshes_nw/fl_wheel.STL" />
            </geometry>
            <material name="">
                <color rgba="0.75294 0.75294 0.75294 1" />
            </material>
        </visual>
        <collision>
            <origin xyz="0 0 0" rpy="0 0 0" />
            <geometry>
                <mesh filename="meshes_nw/fl_wheel.STL" />
            </geometry>
        </collision>
    </link>
    <joint name="fl_wheel" type="revolute">
        <origin xyz="0.20781 -0.0005 -0.082411" rpy="0 0 0" />
        <parent link="fl_calf" />
        <child link="fl_wheel" />
        <axis xyz="0 1 0" />
        <limit lower="-2" upper="2" effort="60" velocity="50" />
    </joint>

    <link name="fr_hip">
        <inertial>
            <origin xyz="72.51E-03 -0.27E-03 0.25E-03" rpy="0 0 0"/>
            <mass value="1523.03E-03"/>
            <inertia ixx="1695238.76E-09" ixy="4381.47E-09" ixz="-26504.81E-09" iyy="3320625.89E-09" iyz="-5709.18E-09" izz="2277111.64E-09"/>
        </inertial>
        <visual>
            <origin xyz="0 0 0" rpy="0 0 0"/>
            <geometry>
                <mesh filename="meshes_nw/fr_hip.STL"/>
            </geometry>
            <material name="">
                <color rgba="0.752941176470588 0.752941176470588 0.752941176470588 1"/>
            </material>
        </visual>
        <collision>
            <origin xyz="0 0 0" rpy="0 0 0"/>
            <geometry>
                <mesh filename="meshes_nw/fr_hip.STL"/>
            </geometry>
        </collision>
    </link>
    <joint name="fr_hip_roll" type="revolute">
        <origin xyz="0.2096 -0.07 0" rpy="0 0 0"/>
        <parent link="base_link"/>
        <child link="fr_hip"/>
        <axis xyz="-1 0 0"/>
        <limit lower="-1.57" upper="1.57" effort="60" velocity="50"/>
    </joint>
    <link name="fr_thigh">
        <inertial>
            <origin xyz="-29.35E-03 -62.17E-03 -0.06E-03" rpy="0 0 0"/>
            <mass value="2472.33E-03"/>
            <inertia ixx="3618059.64E-09" ixy="1851525.59E-09" ixz="-14488.61E-09" iyy="14798148.68E-09" iyz="6908.86E-09" izz="14471209.75E-09"/>
        </inertial>
        <visual>
            <origin xyz="0 0 0" rpy="0 0 0"/>
            <geometry>
                <mesh filename="meshes_nw/fr_thigh.STL"/>
            </geometry>
            <material name="">
                <color rgba="0.752941176470588 0.752941176470588 0.752941176470588 1"/>
            </material>
        </visual>
        <collision>
            <origin xyz="0 0 0" rpy="0 0 0"/>
            <geometry>
                <mesh filename="meshes_nw/fr_thigh.STL"/>
            </geometry>
        </collision>
    </link>
    <joint name="fr_hip_pitch" type="revolute">
        <origin xyz="0.074 -0.0189 0" rpy="0 0 0"/>
        <parent link="fr_hip"/>
        <child link="fr_thigh"/>
        <axis xyz="0 1 0"/>
        <limit lower="-3.14" upper="0" effort="60" velocity="50"/>
    </joint>
    <link name="fr_calf">
        <inertial>
            <origin xyz="0.130801693969533 0.00714942801261559 -0.0568139509368908" rpy="0 0 0"/>
            <mass value="0.395347498939788"/>
            <inertia ixx="0.000129068476386095" ixy="-4.39089089966169E-06" ixz="0.000208721514997643" iyy="0.00109851935217986" iyz="4.45108024553873E-06" izz="0.00102034352196428"/>
        </inertial>
        <visual>
            <origin xyz="0 0 0" rpy="0 0 0"/>
            <geometry>
                <mesh filename="meshes_nw/fr_calf.STL"/>
            </geometry>
            <material name="">
                <color rgba="0.752941176470588 0.752941176470588 0.752941176470588 1"/>
            </material>
        </visual>
        <collision>
            <origin xyz="0 0 0" rpy="0 0 0"/>
            <geometry>
                <mesh filename="meshes_nw/fr_calf.STL"/>
            </geometry>
        </collision>
    </link>
    <joint name="fr_knee" type="revolute">
        <origin xyz="-0.26 -0.0875 0" rpy="0 0 0"/>
        <parent link="fr_thigh"/>
        <child link="fr_calf"/>
        <axis xyz="0 1 0"/>
        <limit lower="0" upper="3.14" effort="60" velocity="50"/>
    </joint>

    <link name="fr_wheel">
        <inertial>
            <origin xyz="-6.4629E-05 5.464E-05 0.0011936" rpy="0 0 0" />
            <mass value="0.023963" />
            <inertia ixx="2.4232E-06" ixy="1.7509E-08" ixz="3.4689E-07" iyy="3.7765E-06" iyz="-1.0175E-08" izz="4.0982E-06" />
        </inertial>
        <visual>
            <origin xyz="0 0 0" rpy="0 0 0" />
            <geometry>
                <mesh filename="meshes_nw/fr_wheel.STL" />
            </geometry>
            <material name="">
                <color rgba="0.75294 0.75294 0.75294 1" />
            </material>
        </visual>
        <collision>
            <origin xyz="0 0 0" rpy="0 0 0" />
            <geometry>
                <mesh filename="meshes_nw/fr_wheel.STL" />
            </geometry>
        </collision>
    </link>
    <joint name="fr_wheel" type="revolute">
        <origin xyz="0.20781 0.0005 -0.082411" rpy="0 0 0" />
        <parent link="fr_calf" />
        <child link="fr_wheel" />
        <axis xyz="0 1 0" />
        <limit lower="-2" upper="2" effort="60" velocity="50" />
    </joint>

    <link name="rl_hip">
        <inertial>
            <origin xyz="-72.51E-03 0.27E-03 0.25E-03" rpy="0 0 0"/>
            <mass value="1523.03E-03"/>
            <inertia ixx="1695446.28E-09" ixy="-25221.86E-09" ixz="26504.81E-09" iyy="3320625.89E-09" iyz="5709.18E-09" izz="2277111.64E-09"/>
        </inertial>
        <visual>
            <origin xyz="0 0 0" rpy="0 0 0"/>
            <geometry>
                <mesh filename="meshes_nw/rl_hip.STL"/>
            </geometry>
            <material name="">
                <color rgba="0.752941176470588 0.752941176470588 0.752941176470588 1"/>
            </material>
        </visual>
        <collision>
            <origin xyz="0 0 0" rpy="0 0 0"/>
            <geometry>
                <mesh filename="meshes_nw/rl_hip.STL"/>
            </geometry>
        </collision>
    </link>
    <joint name="rl_hip_roll" type="revolute">
        <origin xyz="-0.2096 0.07 0" rpy="0 0 0"/>
        <parent link="base_link"/>
        <child link="rl_hip"/>
        <axis xyz="1 0 0"/>
        <limit lower="-1.57" upper="1.57" effort="60" velocity="50"/>
    </joint>
    <link name="rl_thigh">
        <inertial>
            <origin xyz="-31.16E-03 60.66E-03 0.02E-03" rpy="0 0 0"/>
            <mass value="2324.70E-03"/>
            <inertia ixx="3245856.06E-09" ixy="-1927888.88E-09" ixz="16621.48E-09" iyy="14234186.83E-09" iyz="3681.40E-09" izz="13967700.29E-09"/>
        </inertial>
        <visual>
            <origin xyz="0 0 0" rpy="0 0 0"/>
            <geometry>
                <mesh filename="meshes_nw/rl_thigh.STL"/>
            </geometry>
            <material name="">
                <color rgba="0.752941176470588 0.752941176470588 0.752941176470588 1"/>
            </material>
        </visual>
        <collision>
            <origin xyz="0 0 0" rpy="0 0 0"/>
            <geometry>
                <mesh filename="meshes_nw/rl_thigh.STL"/>
            </geometry>
        </collision>
    </link>
    <joint name="rl_hip_pitch" type="revolute">
        <origin xyz="-0.074 0.0189 0" rpy="0 0 0"/>
        <parent link="rl_hip"/>
        <child link="rl_thigh"/>
        <axis xyz="0 -1 0"/>
        <limit lower="-3.14" upper="0" effort="60" velocity="50"/>
    </joint>
    <link name="rl_calf">
        <inertial>
            <origin xyz="0.13129 -0.0071749 -0.056768" rpy="0 0 0"/>
            <mass value="0.39383"/>
            <inertia ixx="0.00012955" ixy="4.751E-06" ixz="0.00020885" iyy="0.0010985" iyz="-3.9901E-06" izz="0.0010198"/>
        </inertial>
        <visual>
            <origin xyz="0 0 0" rpy="0 0 0"/>
            <geometry>
                <mesh filename="meshes_nw/rl_calf.STL"/>
            </geometry>
            <material name="">
                <color rgba="0.75294 0.75294 0.75294 1"/>
            </material>
        </visual>
        <collision>
            <origin xyz="0 0 0" rpy="0 0 0"/>
            <geometry>
                <mesh filename="meshes_nw/rl_calf.STL"/>
            </geometry>
        </collision>
    </link>
    <joint name="rl_knee" type="revolute">
        <origin xyz="-0.26 0.0875 0" rpy="0 0 0"/>
        <parent link="rl_thigh"/>
        <child link="rl_calf"/>
        <axis xyz="0 -1 0"/>
        <limit lower="0" upper="3.14" effort="60" velocity="50"/>
    </joint>

    <link name="rl_wheel">
        <inertial>
            <origin xyz="-6.4629E-05 5.464E-05 0.0011936" rpy="0 0 0" />
            <mass value="0.023963" />
            <inertia ixx="2.4232E-06" ixy="1.7509E-08" ixz="3.4689E-07" iyy="3.7765E-06" iyz="-1.0175E-08" izz="4.0982E-06" />
        </inertial>
        <visual>
            <origin xyz="0 0 0" rpy="0 0 0" />
            <geometry>
                <mesh filename="meshes_nw/rl_wheel.STL" />
            </geometry>
            <material name="">
                <color rgba="0.75294 0.75294 0.75294 1" />
            </material>
        </visual>
        <collision>
            <origin xyz="0 0 0" rpy="0 0 0" />
            <geometry>
                <mesh filename="meshes_nw/rl_wheel.STL" />
            </geometry>
        </collision>
    </link>
    <joint name="rl_wheel" type="revolute">
        <origin xyz="0.20781 -0.0005 -0.082411" rpy="0 0 0" />
        <parent link="rl_calf" />
        <child link="rl_wheel" />
        <axis xyz="0 1 0" />
        <limit lower="-2" upper="2" effort="60" velocity="50" />
    </joint>

    <link name="rr_hip">
        <inertial>
            <origin xyz="-72.35E-03 -0.30E-03 0.0" rpy="0 0 0"/>
            <mass value="1519.39E-03"/>
            <inertia ixx="1694040.51E-09" ixy="-771.73E-09" ixz="-13604.23E-09" iyy="3302452.37E-09" iyz="-4147.49E-09" izz="2258493.73E-09"/>
        </inertial>
        <visual>
            <origin xyz="0 0 0" rpy="0 0 0"/>
            <geometry>
                <mesh filename="meshes_nw/rr_hip.STL"/>
            </geometry>
            <material name="">
                <color rgba="0.752941176470588 0.752941176470588 0.752941176470588 1"/>
            </material>
        </visual>
        <collision>
            <origin xyz="0 0 0" rpy="0 0 0"/>
            <geometry>
                <mesh filename="meshes_nw/rr_hip.STL"/>
            </geometry>
        </collision>
    </link>
    <joint name="rr_hip_roll" type="revolute">
        <origin xyz="-0.2096 -0.07 0" rpy="0 0 0"/>
        <parent link="base_link"/>
        <child link="rr_hip"/>
        <axis xyz="1 0 0"/>
        <limit lower="-1.57" upper="1.57" effort="60" velocity="50"/>
    </joint>
    <link name="rr_thigh">
        <inertial>
            <origin xyz="-29.35E-03 -62.17E-03 -0.06E-03" rpy="0 0 0"/>
            <mass value="2472.33E-03"/>
            <inertia ixx="3618059.64E-09" ixy="1851525.59E-09" ixz="-14488.61E-09" iyy="14798148.68E-09" iyz="6908.86E-09" izz="14471209.75E-09"/>
        </inertial>
        <visual>
            <origin xyz="0 0 0" rpy="0 0 0"/>
            <geometry>
                <mesh filename="meshes_nw/rr_thigh.STL"/>
            </geometry>
            <material name="">
                <color rgba="0.752941176470588 0.752941176470588 0.752941176470588 1"/>
            </material>
        </visual>
        <collision>
            <origin xyz="0 0 0" rpy="0 0 0"/>
            <geometry>
                <mesh filename="meshes_nw/rr_thigh.STL"/>
            </geometry>
        </collision>
    </link>
    <joint name="rr_hip_pitch" type="revolute">
        <origin xyz="-0.074 -0.0189 0" rpy="0 0 0"/>
        <parent link="rr_hip"/>
        <child link="rr_thigh"/>
        <axis xyz="0 1 0"/>
        <limit lower="-3.14" upper="0" effort="60" velocity="50"/>
    </joint>
    <link name="rr_calf">
        <inertial>
            <origin xyz="0.130801693981397 0.00714942801534552 -0.0568139509419227" rpy="0 0 0"/>
            <mass value="0.395347498980154"/>
            <inertia ixx="0.000129068476385776" ixy="-4.39089090049954E-06" ixz="0.000208721514997669" iyy="0.00109851935218243" iyz="4.45108024519339E-06" izz="0.00102034352196753"/>
        </inertial>
        <visual>
            <origin xyz="0 0 0" rpy="0 0 0"/>
            <geometry>
                <mesh filename="meshes_nw/rr_calf.STL"/>
            </geometry>
            <material name="">
                <color rgba="0.752941176470588 0.752941176470588 0.752941176470588 1"/>
            </material>
        </visual>
        <collision>
            <origin xyz="0 0 0" rpy="0 0 0"/>
            <geometry>
                <mesh filename="meshes_nw/rr_calf.STL"/>
            </geometry>
        </collision>
    </link>
    <joint name="rr_knee" type="revolute">
        <origin xyz="-0.26 -0.0875 0" rpy="0 0 0"/>
        <parent link="rr_thigh"/>
        <child link="rr_calf"/>
        <axis xyz="0 1 0"/>
        <limit lower="0" upper="3.14" effort="60" velocity="50"/>
    </joint>

    <link name="rr_wheel">
        <inertial>
            <origin xyz="-6.4629E-05 5.464E-05 0.0011936" rpy="0 0 0" />
            <mass value="0.023963" />
            <inertia ixx="2.4232E-06" ixy="1.7509E-08" ixz="3.4689E-07" iyy="3.7765E-06" iyz="-1.0175E-08" izz="4.0982E-06" />
        </inertial>
        <visual>
            <origin xyz="0 0 0" rpy="0 0 0" />
            <geometry>
                <mesh filename="meshes_nw/rr_wheel.STL" />
            </geometry>
            <material name="">
                <color rgba="0.75294 0.75294 0.75294 1" />
            </material>
        </visual>
        <collision>
            <origin xyz="0 0 0" rpy="0 0 0" />
            <geometry>
                <mesh filename="meshes_nw/rr_wheel.STL" />
            </geometry>
        </collision>
    </link>
    <joint name="rr_wheel" type="revolute">
        <origin xyz="0.20781 0.0005 -0.082411" rpy="0 0 0" />
        <parent link="rr_calf" />
        <child link="rr_wheel" />
        <axis xyz="0 1 0" />
        <limit lower="-2" upper="2" effort="60" velocity="50" />
    </joint>
</robot>
